Workbook
Name DAFTAR_KELAS: 'TABEL KONVERSI'!$B$26:$B$61
Name GURU_1: 'ENTRY DATA'!$G$10
Name GURU_10: 'ENTRY DATA'!$DK$10
Name GURU_11: 'ENTRY DATA'!$DW$10
Name GURU_12: 'ENTRY DATA'!$EI$10
Name GURU_13: 'ENTRY DATA'!$EU$10
Name GURU_14: 'ENTRY DATA'!$FG$10
Name GURU_15: 'ENTRY DATA'!$FS$10
Name GURU_16: 'ENTRY DATA'!$GE$10
Name GURU_2: 'ENTRY DATA'!$S$10
Name GURU_3: 'ENTRY DATA'!$AE$10
Name GURU_4: 'ENTRY DATA'!$AQ$10
Name GURU_5: 'ENTRY DATA'!$BC$10
Name GURU_6: 'ENTRY DATA'!$BO$10
Name GURU_7: 'ENTRY DATA'!$CA$10
Name GURU_8: 'ENTRY DATA'!$CM$10
Name GURU_9: 'ENTRY DATA'!$CY$10
Name JURUSAN: 'ENTRY DATA'!$C$1
Name KELAS: 'ENTRY DATA'!$C$2
Name KKM_1: 'ENTRY DATA'!$G$9
Name KKM_10: 'ENTRY DATA'!$DK$9
Name KKM_11: 'ENTRY DATA'!$DW$9
Name KKM_12: 'ENTRY DATA'!$EI$9
Name KKM_13: 'ENTRY DATA'!$EU$9
Name KKM_14: 'ENTRY DATA'!$FG$9
Name KKM_15: 'ENTRY DATA'!$FS$9
Name KKM_16: 'ENTRY DATA'!$GE$9
Name KKM_2: 'ENTRY DATA'!$S$9
Name KKM_3: 'ENTRY DATA'!$AE$9
Name KKM_4: 'ENTRY DATA'!$AQ$9
Name KKM_5: 'ENTRY DATA'!$BC$9
Name KKM_6: 'ENTRY DATA'!$BO$9
Name KKM_7: 'ENTRY DATA'!$CA$9
Name KKM_8: 'ENTRY DATA'!$CM$9
Name KKM_9: 'ENTRY DATA'!$CY$9
Name NIP_KEPSEK: 'ENTRY DATA'!$G$4
Name NIP_WALIKELAS: 'ENTRY DATA'!$G$2
Name NM_KEPSEK: 'ENTRY DATA'!$G$3
Name NM_WALIKELAS: 'ENTRY DATA'!$G$1
Name SEMESTER: 'ENTRY DATA'!$C$3
Name TH_PELAJARAN: 'ENTRY DATA'!$C$4
Name TITIMANGSA: 'ENTRY DATA'!$C$5

Sheet ENTRY DATA
A1: Jurusan/Program | C1: MIPA | E1: Nama Wali Kelas | G1: Drs. Ahmad Fathony | IJ1: =IZ13 -> -
A2: Kelas | C2: X MIPA-1 | E2: NIP Wali Kelas | G2: 12345678 123456 1 123
A3: Semester | C3: 1 | E3: Nama Kepala Sekolah | G3: H. Abdul Basith, M.Pd.
A4: Th Pelajaran | C4: 2022/2023 | E4: NIP Kepala Sekolah | G4: 12341234 123123 1 234
A5: Titimangsa Raport | C5: Bandung, 10 Oktober 2022
A7: NO | B7: NIS | C7: NISN | D7: NAMA PESERTA DIDIK | E7: L/P | F7: KELOMPOK A (UMUM) | BZ7: KELOMPOK B (UMUM) | DV7: KELOMPOK C (PEMINATAN) | FR7: LINTAS MINAT / PENDALAMAN MINAT | GP7: SIKAP | IH7: EKSTRAKURIKULER | IW7: KEHADIRAN | IZ7: CATATAN WALI KELAS | JA7: JUMLAH NILAI | JB7: RANKING
F8: Pendidikan Agama Dan Budi Pekerti | R8: Pendidikan Pancasila dan Kewarganegaraan | AD8: Bahasa Indonesia | AP8: Matematika | BB8: Sejarah Indonesia | BN8: Bahasa Inggris | BZ8: Seni Budaya | CL8: Pendidikan Jasmani, Olah Raga dan Kesehatan | CX8: Prakarya dan Kewirausahaan | DJ8: Bahasa Sunda | DV8: =IF(C1="MIPA","Matematika","Geografi") -> Matematika | EH8: =IF(C1="MIPA","Biologi","Sejarah") -> Biologi | ET8: =IF(C1="MIPA","Fisika","Sosiologi") -> Fisika | FF8: =IF(C1="MIPA","Kimia","Ekonomi") -> Kimia | FR8: - | GD8: - | GP8: SIKAP SPIRITUAL | HL8: SIKAP SOSIAL
F9: KKM : | G9: 75 | R9: KKM : | S9: 75 | AD9: KKM : | AE9: 75 | AP9: KKM : | AQ9: 75 | BB9: KKM : | BC9: 75 | BN9: KKM : | BO9: 75 | BZ9: KKM : | CA9: 75 | CL9: KKM : | CM9: 75 | CX9: KKM : | CY9: 75 | DJ9: KKM : | DK9: 75 | DV9: KKM : | DW9: 75 | EH9: KKM : | EI9: 75 | ET9: KKM : | EU9: 75 | FF9: KKM : | FG9: 75 | FR9: KKM : | FS9: 75 | GD9: KKM : | GE9: 75
F10: Nm. Guru : | R10: Nm. Guru : | AD10: Nm. Guru : | AP10: Nm. Guru : | BB10: Nm. Guru : | BN10: Nm. Guru : | BZ10: Nm. Guru : | CL10: Nm. Guru : | CX10: Nm. Guru : | DJ10: Nm. Guru : | DV10: Nm. Guru : | EH10: Nm. Guru : | ET10: Nm. Guru : | FF10: Nm. Guru : | FR10: Nm. Guru : | GD10: Nm. Guru :
F11: PENGETAHUAN | G11: KETERAMPILAN | H11: SIKAP | J11: NILAI JADI | L11: KODE | N11: Penget | P11: Ketramp | R11: PENGETAHUAN | S11: KETERAMPILAN | T11: SIKAP | V11: NILAI JADI | X11: KODE | Z11: Penget | AB11: Ketramp | AD11: PENGETAHUAN | AE11: KETERAMPILAN | AF11: SIKAP | AH11: NILAI JADI | AJ11: KODE | AL11: Penget | AN11: Ketramp | AP11: PENGETAHUAN | AQ11: KETERAMPILAN | AR11: SIKAP | AT11: NILAI JADI | AV11: KODE | AX11: Penget | AZ11: Ketramp | BB11: PENGETAHUAN | BC11: KETERAMPILAN | BD11: SIKAP | BF11: NILAI JADI | BH11: KODE | BJ11: Penget | BL11: Ketramp | BN11: PENGETAHUAN | BO11: KETERAMPILAN | BP11: SIKAP | BR11: NILAI JADI | BT11: KODE | BV11: Penget | BX11: Ketramp | BZ11: PENGETAHUAN | CA11: KETERAMPILAN | CB11: SIKAP | CD11: NILAI JADI | CF11: KODE | CH11: Penget | CJ11: Ketramp | CL11: PENGETAHUAN | CM11: KETERAMPILAN | CN11: SIKAP | CP11: NILAI JADI | CR11: KODE | CT11: Penget | CV11: Ketramp | CX11: PENGETAHUAN | CY11: KETERAMPILAN | CZ11: SIKAP | DB11: NILAI JADI | DD11: KODE | DF11: Penget | DH11: Ketramp | DJ11: PENGETAHUAN | DK11: KETERAMPILAN | DL11: SIKAP | DN11: NILAI JADI | DP11: KODE | DR11: Penget | DT11: Ketramp | DV11: PENGETAHUAN | DW11: KETERAMPILAN | DX11: SIKAP | DZ11: NILAI JADI | EB11: KODE | ED11: Penget | EF11: Ketramp | EH11: PENGETAHUAN | EI11: KETERAMPILAN | EJ11: SIKAP | EL11: NILAI JADI | EN11: KODE | EP11: Penget | ER11: Ketramp | ET11: PENGETAHUAN | EU11: KETERAMPILAN | EV11: SIKAP | EX11: NILAI JADI | EZ11: KODE | FB11: Penget | FD11: Ketramp | FF11: PENGETAHUAN | FG11: KETERAMPILAN | FH11: SIKAP | FJ11: NILAI JADI | FL11: KODE | FN11: Penget | FP11: Ketramp | FR11: PENGETAHUAN | FS11: KETERAMPILAN | FT11: SIKAP | FV11: NILAI JADI | FX11: KODE | FZ11: Penget | GB11: Ketramp | GD11: PENGETAHUAN | GE11: KETERAMPILAN | GF11: SIKAP | GH11: NILAI JADI | GJ11: KODE | GL11: Penget | GN11: Ketramp | HF11: Jml. Kemunculan | HJ11: Predikat | HK11: Deskripsi | IB11: Jml. Kemunculan | IF11: Predikat | IG11: Deskripsi | IH11: EksKul 1 | II11: NILAI | IJ11: N.Eks1 | IK11: EksKul 2 | IL11: NILAI | IM11: N.Eks2 | IN11: EksKul 3 | IO11: NILAI | IP11: N.Eks3 | IQ11: EksKul 4 | IR11: NILAI | IS11: N.Eks4 | IT11: EksKul 5 | IU11: NILAI | IV11: N.Eks5 | IW11: S | IX11: I | IY11: TK
H12: SPI | I12: SOS | J12: P | K12: K | L12: Peng | M12: Ket | N12: Nil | O12: Pred | P12: Nil | Q12: Pred | T12: SPI | U12: SOS | V12: P | W12: K | X12: Peng | Y12: Ket | Z12: Nil | AA12: Pred | AB12: Nil | AC12: Pred | AF12: SPI | AG12: SOS | AH12: P | AI12: K | AJ12: Peng | AK12: Ket | AL12: Nil | AM12: Pred | AN12: Nil | AO12: Pred | AR12: SPI | AS12: SOS | AT12: P | AU12: K | AV12: Peng | AW12: Ket | AX12: Nil | AY12: Pred | AZ12: Nil | BA12: Pred | BD12: SPI | BE12: SOS | BF12: P | BG12: K | BH12: Peng | BI12: Ket | BJ12: Nil | BK12: Pred | BL12: Nil | BM12: Pred | BP12: SPI | BQ12: SOS | BR12: P | BS12: K | BT12: Peng | BU12: Ket | BV12: Nil | BW12: Pred | BX12: Nil | BY12: Pred | CB12: SPI | CC12: SOS | CD12: P | CE12: K | CF12: Peng | CG12: Ket | CH12: Nil | CI12: Pred | CJ12: Nil | CK12: Pred | CN12: SPI | CO12: SOS | CP12: P | CQ12: K | CR12: Peng | CS12: Ket | CT12: Nil | CU12: Pred | CV12: Nil | CW12: Pred | CZ12: SPI | DA12: SOS | DB12: P | DC12: K | DD12: Peng | DE12: Ket | DF12: Nil | DG12: Pred | DH12: Nil | DI12: Pred | DL12: SPI | DM12: SOS | DN12: P | DO12: K | DP12: Peng | DQ12: Ket | DR12: Nil | DS12: Pred | DT12: Nil | DU12: Pred | DX12: SPI | DY12: SOS | DZ12: P | EA12: K | EB12: Peng | EC12: Ket | ED12: Nil | EE12: Pred | EF12: Nil | EG12: Pred | EJ12: SPI | EK12: SOS | EL12: P | EM12: K | EN12: Peng | EO12: Ket | EP12: Nil | EQ12: Pred | ER12: Nil | ES12: Pred | EV12: SPI | EW12: SOS | EX12: P | EY12: K | EZ12: Peng | FA12: Ket | FB12: Nil | FC12: Pred | FD12: Nil | FE12: Pred | FH12: SPI | FI12: SOS | FJ12: P | FK12: K | FL12: Peng | FM12: Ket | FN12: Nil | FO12: Pred | FP12: Nil | FQ12: Pred | FT12: SPI | FU12: SOS | FV12: P | FW12: K | FX12: Peng | FY12: Ket | FZ12: Nil | GA12: Pred | GB12: Nil | GC12: Pred | GF12: SPI | GG12: SOS | GH12: P | GI12: K | GJ12: Peng | GK12: Ket | GL12: Nil | GM12: Pred | GN12: Nil | GO12: Pred | HF12: A | HG12: B | HH12: C | HI12: D | IB12: A | IC12: B | ID12: C | IE12: D
A13: 1 | J13: =IF(F13<>"",ROUND(F13,0),"") | K13: =IF(G13<>"",ROUND(G13,0),"") | L13: =IF(J13<>"",IF(AND(J13>='TABEL KONVERSI'!$B$3,'ENTRY DATA'!J13<='TABEL KONVERSI'!$C$3),1,IF(AND(J13>='TABEL KONVERSI'!$B$4,'ENTRY DATA'!J13<='TABEL KONVERSI'!$C$4),2,IF(AND(J13>='TABEL KONVERSI'!$B$5,'ENTRY DATA'!J13<='TABEL KONVERSI'!$C$5),3,IF(AND(J13>='TABEL KONVERSI'!$B$6,'ENTRY DATA'!J13<='TABEL KONVERSI'!$C$6),4,"")))),"-") -> - | M13: =IF(K13<>"",IF(AND(K13>='TABEL KONVERSI'!$B$3,'ENTRY DATA'!K13<='TABEL KONVERSI'!$C$3),1,IF(AND(K13>='TABEL KONVERSI'!$B$4,'ENTRY DATA'!K13<='TABEL KONVERSI'!$C$4),2,IF(AND(K13>='TABEL KONVERSI'!$B$5,'ENTRY DATA'!K13<='TABEL KONVERSI'!$C$5),3,IF(AND(K13>='TABEL KONVERSI'!$B$6,'ENTRY DATA'!K13<='TABEL KONVERSI'!$C$6),4,"")))),"-") -> - | N13: =IF(J13<>"",J13,"-") -> - | O13: =VLOOKUP(L13,'TABEL KONVERSI'!$A$3:$D$7,4) -> - | P13: =IF(K13<>"",K13,"-") -> - | Q13: =VLOOKUP(M13,'TABEL KONVERSI'!$A$3:$D$7,4) -> - | V13: =IF(R13<>"",ROUND(R13,0),"") | W13: =IF(S13<>"",ROUND(S13,0),"") | X13: =IF(V13<>"",IF(AND(V13>='TABEL KONVERSI'!$B$3,'ENTRY DATA'!V13<='TABEL KONVERSI'!$C$3),1,IF(AND(V13>='TABEL KONVERSI'!$B$4,'ENTRY DATA'!V13<='TABEL KONVERSI'!$C$4),2,IF(AND(V13>='TABEL KONVERSI'!$B$5,'ENTRY DATA'!V13<='TABEL KONVERSI'!$C$5),3,IF(AND(V13>='TABEL KONVERSI'!$B$6,'ENTRY DATA'!V13<='TABEL KONVERSI'!$C$6),4,"")))),"-") -> - | Y13: =IF(W13<>"",IF(AND(W13>='TABEL KONVERSI'!$B$3,'ENTRY DATA'!W13<='TABEL KONVERSI'!$C$3),1,IF(AND(W13>='TABEL KONVERSI'!$B$4,'ENTRY DATA'!W13<='TABEL KONVERSI'!$C$4),2,IF(AND(W13>='TABEL KONVERSI'!$B$5,'ENTRY DATA'!W13<='TABEL KONVERSI'!$C$5),3,IF(AND(W13>='TABEL KONVERSI'!$B$6,'ENTRY DATA'!W13<='TABEL KONVERSI'!$C$6),4,"")))),"-") -> - | Z13: =IF(V13<>"",V13,"-") -> - | AA13: =VLOOKUP(X13,'TABEL KONVERSI'!$A$3:$D$7,4) -> - | AB13: =IF(W13<>"",W13,"-") -> - | AC13: =VLOOKUP(Y13,'TABEL KONVERSI'!$A$3:$D$7,4) -> - | AH13: =IF(AD13<>"",ROUND(AD13,0),"") | AI13: =IF(AE13<>"",ROUND(AE13,0),"") | AJ13: =IF(AH13<>"",IF(AND(AH13>='TABEL KONVERSI'!$B$3,'ENTRY DATA'!AH13<='TABEL KONVERSI'!$C$3),1,IF(AND(AH13>='TABEL KONVERSI'!$B$4,'ENTRY DATA'!AH13<='TABEL KONVERSI'!$C$4),2,IF(AND(AH13>='TABEL KONVERSI'!$B$5,'ENTRY DATA'!AH13<='TABEL KONVERSI'!$C$5),3,IF(AND(AH13>='TABEL KONVERSI'!$B$6,'ENTRY DATA'!AH13<='TABEL KONVERSI'!$C$6),4,"")))),"-") -> - | AK13: =IF(AI13<>"",IF(AND(AI13>='TABEL KONVERSI'!$B$3,'ENTRY DATA'!AI13<='TABEL KONVERSI'!$C$3),1,IF(AND(AI13>='TABEL KONVERSI'!$B$4,'ENTRY DATA'!AI13<='TABEL KONVERSI'!$C$4),2,IF(AND(AI13>='TABEL KONVERSI'!$B$5,'ENTRY DATA'!AI13<='TABEL KONVERSI'!$C$5),3,IF(AND(AI13>='TABEL KONVERSI'!$B$6,'ENTRY DATA'!AI13<='TABEL KONVERSI'!$C$6),4,"")))),"-") -> - | AL13: =IF(AH13<>"",AH13,"-") -> - | AM13: =VLOOKUP(AJ13,'TABEL KONVERSI'!$A$3:$D$7,4) -> - | AN13: =IF(AI13<>"",AI13,"-") -> - | AO13: =VLOOKUP(AK13,'TABEL KONVERSI'!$A$3:$D$7,4) -> - | AT13: =IF(AP13<>"",ROUND(AP13,0),"") | AU13: =IF(AQ13<>"",ROUND(AQ13,0),"") | AV13: =IF(AT13<>"",IF(AND(AT13>='TABEL KONVERSI'!$B$3,'ENTRY DATA'!AT13<='TABEL KONVERSI'!$C$3),1,IF(AND(AT13>='TABEL KONVERSI'!$B$4,'ENTRY DATA'!AT13<='TABEL KONVERSI'!$C$4),2,IF(AND(AT13>='TABEL KONVERSI'!$B$5,'ENTRY DATA'!AT13<='TABEL KONVERSI'!$C$5),3,IF(AND(AT13>='TABEL KONVERSI'!$B$6,'ENTRY DATA'!AT13<='TABEL KONVERSI'!$C$6),4,"")))),"-") -> - | AW13: =IF(AU13<>"",IF(AND(AU13>='TABEL KONVERSI'!$B$3,'ENTRY DATA'!AU13<='TABEL KONVERSI'!$C$3),1,IF(AND(AU13>='TABEL KONVERSI'!$B$4,'ENTRY DATA'!AU13<='TABEL KONVERSI'!$C$4),2,IF(AND(AU13>='TABEL KONVERSI'!$B$5,'ENTRY DATA'!AU13<='TABEL KONVERSI'!$C$5),3,IF(AND(AU13>='TABEL KONVERSI'!$B$6,'ENTRY DATA'!AU13<='TABEL KONVERSI'!$C$6),4,"")))),"-") -> - | AX13: =IF(AT13<>"",AT13,"-") -> - | AY13: =VLOOKUP(AV13,'TABEL KONVERSI'!$A$3:$D$7,4) -> - | AZ13: =IF(AU13<>"",AU13,"-") -> - | BA13: =VLOOKUP(AW13,'TABEL KONVERSI'!$A$3:$D$7,4) -> - | BF13: =IF(BB13<>"",ROUND(BB13,0),"") | BG13: =IF(BC13<>"",ROUND(BC13,0),"") | BH13: =IF(BF13<>"",IF(AND(BF13>='TABEL KONVERSI'!$B$3,'ENTRY DATA'!BF13<='TABEL KONVERSI'!$C$3),1,IF(AND(BF13>='TABEL KONVERSI'!$B$4,'ENTRY DATA'!BF13<='TABEL KONVERSI'!$C$4),2,IF(AND(BF13>='TABEL KONVERSI'!$B$5,'ENTRY DATA'!BF13<='TABEL KONVERSI'!$C$5),3,IF(AND(BF13>='TABEL KONVERSI'!$B$6,'ENTRY DATA'!BF13<='TABEL KONVERSI'!$C$6),4,"")))),"-") -> - | BI13: =IF(BG13<>"",IF(AND(BG13>='TABEL KONVERSI'!$B$3,'ENTRY DATA'!BG13<='TABEL KONVERSI'!$C$3),1,IF(AND(BG13>='TABEL KONVERSI'!$B$4,'ENTRY DATA'!BG13<='TABEL KONVERSI'!$C$4),2,IF(AND(BG13>='TABEL KONVERSI'!$B$5,'ENTRY DATA'!BG13<='TABEL KONVERSI'!$C$5),3,IF(AND(BG13>='TABEL KONVERSI'!$B$6,'ENTRY DATA'!BG13<='TABEL KONVERSI'!$C$6),4,"")))),"-") -> - | BJ13: =IF(BF13<>"",BF13,"-") -> - | BK13: =VLOOKUP(BH13,'TABEL KONVERSI'!$A$3:$D$7,4) -> - | BL13: =IF(BG13<>"",BG13,"-") -> - | BM13: =VLOOKUP(BI13,'TABEL KONVERSI'!$A$3:$D$7,4) -> - | BR13: =IF(BN13<>"",ROUND(BN13,0),"") | BS13: =IF(BO13<>"",ROUND(BO13,0),"") | BT13: =IF(BR13<>"",IF(AND(BR13>='TABEL KONVERSI'!$B$3,'ENTRY DATA'!BR13<='TABEL KONVERSI'!$C$3),1,IF(AND(BR13>='TABEL KONVERSI'!$B$4,'ENTRY DATA'!BR13<='TABEL KONVERSI'!$C$4),2,IF(AND(BR13>='TABEL KONVERSI'!$B$5,'ENTRY DATA'!BR13<='TABEL KONVERSI'!$C$5),3,IF(AND(BR13>='TABEL KONVERSI'!$B$6,'ENTRY DATA'!BR13<='TABEL KONVERSI'!$C$6),4,"")))),"-") -> - | BU13: =IF(BS13<>"",IF(AND(BS13>='TABEL KONVERSI'!$B$3,'ENTRY DATA'!BS13<='TABEL KONVERSI'!$C$3),1,IF(AND(BS13>='TABEL KONVERSI'!$B$4,'ENTRY DATA'!BS13<='TABEL KONVERSI'!$C$4),2,IF(AND(BS13>='TABEL KONVERSI'!$B$5,'ENTRY DATA'!BS13<='TABEL KONVERSI'!$C$5),3,IF(AND(BS13>='TABEL KONVERSI'!$B$6,'ENTRY DATA'!BS13<='TABEL KONVERSI'!$C$6),4,"")))),"-") -> - | BV13: =IF(BR13<>"",BR13,"-") -> - | BW13: =VLOOKUP(BT13,'TABEL KONVERSI'!$A$3:$D$7,4) -> - | BX13: =IF(BS13<>"",BS13,"-") -> - | BY13: =VLOOKUP(BU13,'TABEL KONVERSI'!$A$3:$D$7,4) -> - | CD13: =IF(BZ13<>"",ROUND(BZ13,0),"") | CE13: =IF(CA13<>"",ROUND(CA13,0),"") | CF13: =IF(CD13<>"",IF(AND(CD13>='TABEL KONVERSI'!$B$3,'ENTRY DATA'!CD13<='TABEL KONVERSI'!$C$3),1,IF(AND(CD13>='TABEL KONVERSI'!$B$4,'ENTRY DATA'!CD13<='TABEL KONVERSI'!$C$4),2,IF(AND(CD13>='TABEL KONVERSI'!$B$5,'ENTRY DATA'!CD13<='TABEL KONVERSI'!$C$5),3,IF(AND(CD13>='TABEL KONVERSI'!$B$6,'ENTRY DATA'!CD13<='TABEL KONVERSI'!$C$6),4,"")))),"-") -> - | CG13: =IF(CE13<>"",IF(AND(CE13>='TABEL KONVERSI'!$B$3,'ENTRY DATA'!CE13<='TABEL KONVERSI'!$C$3),1,IF(AND(CE13>='TABEL KONVERSI'!$B$4,'ENTRY DATA'!CE13<='TABEL KONVERSI'!$C$4),2,IF(AND(CE13>='TABEL KONVERSI'!$B$5,'ENTRY DATA'!CE13<='TABEL KONVERSI'!$C$5),3,IF(AND(CE13>='TABEL KONVERSI'!$B$6,'ENTRY DATA'!CE13<='TABEL KONVERSI'!$C$6),4,"")))),"-") -> - | CH13: =IF(CD13<>"",CD13,"-") -> - | CI13: =VLOOKUP(CF13,'TABEL KONVERSI'!$A$3:$D$7,4) -> - | CJ13: =IF(CE13<>"",CE13,"-") -> - | CK13: =VLOOKUP(CG13,'TABEL KONVERSI'!$A$3:$D$7,4) -> - | CP13: =IF(CL13<>"",ROUND(CL13,0),"") | CQ13: =IF(CM13<>"",ROUND(CM13,0),"") | CR13: =IF(CP13<>"",IF(AND(CP13>='TABEL KONVERSI'!$B$3,'ENTRY DATA'!CP13<='TABEL KONVERSI'!$C$3),1,IF(AND(CP13>='TABEL KONVERSI'!$B$4,'ENTRY DATA'!CP13<='TABEL KONVERSI'!$C$4),2,IF(AND(CP13>='TABEL KONVERSI'!$B$5,'ENTRY DATA'!CP13<='TABEL KONVERSI'!$C$5),3,IF(AND(CP13>='TABEL KONVERSI'!$B$6,'ENTRY DATA'!CP13<='TABEL KONVERSI'!$C$6),4,"")))),"-") -> - | CS13: =IF(CQ13<>"",IF(AND(CQ13>='TABEL KONVERSI'!$B$3,'ENTRY DATA'!CQ13<='TABEL KONVERSI'!$C$3),1,IF(AND(CQ13>='TABEL KONVERSI'!$B$4,'ENTRY DATA'!CQ13<='TABEL KONVERSI'!$C$4),2,IF(AND(CQ13>='TABEL KONVERSI'!$B$5,'ENTRY DATA'!CQ13<='TABEL KONVERSI'!$C$5),3,IF(AND(CQ13>='TABEL KONVERSI'!$B$6,'ENTRY DATA'!CQ13<='TABEL KONVERSI'!$C$6),4,"")))),"-") -> - | CT13: =IF(CP13<>"",CP13,"-") -> - | CU13: =VLOOKUP(CR13,'TABEL KONVERSI'!$A$3:$D$7,4) -> - | CV13: =IF(CQ13<>"",CQ13,"-") -> - | CW13: =VLOOKUP(CS13,'TABEL KONVERSI'!$A$3:$D$7,4) -> - | DB13: =IF(CX13<>"",ROUND(CX13,0),"") | DC13: =IF(CY13<>"",ROUND(CY13,0),"") | DD13: =IF(DB13<>"",IF(AND(DB13>='TABEL KONVERSI'!$B$3,'ENTRY DATA'!DB13<='TABEL KONVERSI'!$C$3),1,IF(AND(DB13>='TABEL KONVERSI'!$B$4,'ENTRY DATA'!DB13<='TABEL KONVERSI'!$C$4),2,IF(AND(DB13>='TABEL KONVERSI'!$B$5,'ENTRY DATA'!DB13<='TABEL KONVERSI'!$C$5),3,IF(AND(DB13>='TABEL KONVERSI'!$B$6,'ENTRY DATA'!DB13<='TABEL KONVERSI'!$C$6),4,"")))),"-") -> - | DE13: =IF(DC13<>"",IF(AND(DC13>='TABEL KONVERSI'!$B$3,'ENTRY DATA'!DC13<='TABEL KONVERSI'!$C$3),1,IF(AND(DC13>='TABEL KONVERSI'!$B$4,'ENTRY DATA'!DC13<='TABEL KONVERSI'!$C$4),2,IF(AND(DC13>='TABEL KONVERSI'!$B$5,'ENTRY DATA'!DC13<='TABEL KONVERSI'!$C$5),3,IF(AND(DC13>='TABEL KONVERSI'!$B$6,'ENTRY DATA'!DC13<='TABEL KONVERSI'!$C$6),4,"")))),"-") -> - | DF13: =IF(DB13<>"",DB13,"-") -> - | DG13: =VLOOKUP(DD13,'TABEL KONVERSI'!$A$3:$D$7,4) -> - | DH13: =IF(DC13<>"",DC13,"-") -> - | DI13: =VLOOKUP(DE13,'TABEL KONVERSI'!$A$3:$D$7,4) -> - | DN13: =IF(DJ13<>"",ROUND(DJ13,0),"") | DO13: =IF(DK13<>"",ROUND(DK13,0),"") | DP13: =IF(DN13<>"",IF(AND(DN13>='TABEL KONVERSI'!$B$3,'ENTRY DATA'!DN13<='TABEL KONVERSI'!$C$3),1,IF(AND(DN13>='TABEL KONVERSI'!$B$4,'ENTRY DATA'!DN13<='TABEL KONVERSI'!$C$4),2,IF(AND(DN13>='TABEL KONVERSI'!$B$5,'ENTRY DATA'!DN13<='TABEL KONVERSI'!$C$5),3,IF(AND(DN13>='TABEL KONVERSI'!$B$6,'ENTRY DATA'!DN13<='TABEL KONVERSI'!$C$6),4,"")))),"-") -> - | DQ13: =IF(DO13<>"",IF(AND(DO13>='TABEL KONVERSI'!$B$3,'ENTRY DATA'!DO13<='TABEL KONVERSI'!$C$3),1,IF(AND(DO13>='TABEL KONVERSI'!$B$4,'ENTRY DATA'!DO13<='TABEL KONVERSI'!$C$4),2,IF(AND(DO13>='TABEL KONVERSI'!$B$5,'ENTRY DATA'!DO13<='TABEL KONVERSI'!$C$5),3,IF(AND(DO13>='TABEL KONVERSI'!$B$6,'ENTRY DATA'!DO13<='TABEL KONVERSI'!$C$6),4,"")))),"-") -> - | DR13: =IF(DN13<>"",DN13,"-") -> - | DS13: =VLOOKUP(DP13,'TABEL KONVERSI'!$A$3:$D$7,4) -> - | DT13: =IF(DO13<>"",DO13,"-") -> - | DU13: =VLOOKUP(DQ13,'TABEL KONVERSI'!$A$3:$D$7,4) -> - | DZ13: =IF(DV13<>"",ROUND(DV13,0),"") | EA13: =IF(DW13<>"",ROUND(DW13,0),"") | EB13: =IF(DZ13<>"",IF(AND(DZ13>='TABEL KONVERSI'!$B$3,'ENTRY DATA'!DZ13<='TABEL KONVERSI'!$C$3),1,IF(AND(DZ13>='TABEL KONVERSI'!$B$4,'ENTRY DATA'!DZ13<='TABEL KONVERSI'!$C$4),2,IF(AND(DZ13>='TABEL KONVERSI'!$B$5,'ENTRY DATA'!DZ13<='TABEL KONVERSI'!$C$5),3,IF(AND(DZ13>='TABEL KONVERSI'!$B$6,'ENTRY DATA'!DZ13<='TABEL KONVERSI'!$C$6),4,"")))),"-") -> - | EC13: =IF(EA13<>"",IF(AND(EA13>='TABEL KONVERSI'!$B$3,'ENTRY DATA'!EA13<='TABEL KONVERSI'!$C$3),1,IF(AND(EA13>='TABEL KONVERSI'!$B$4,'ENTRY DATA'!EA13<='TABEL KONVERSI'!$C$4),2,IF(AND(EA13>='TABEL KONVERSI'!$B$5,'ENTRY DATA'!EA13<='TABEL KONVERSI'!$C$5),3,IF(AND(EA13>='TABEL KONVERSI'!$B$6,'ENTRY DATA'!EA13<='TABEL KONVERSI'!$C$6),4,"")))),"-") -> - | ED13: =IF(DZ13<>"",DZ13,"-") -> - | EE13: =VLOOKUP(EB13,'TABEL KONVERSI'!$A$3:$D$7,4) -> - | EF13: =IF(EA13<>"",EA13,"-") -> - | EG13: =VLOOKUP(EC13,'TABEL KONVERSI'!$A$3:$D$7,4) -> - | EL13: =IF(EH13<>"",ROUND(EH13,0),"") | EM13: =IF(EI13<>"",ROUND(EI13,0),"") | EN13: =IF(EL13<>"",IF(AND(EL13>='TABEL KONVERSI'!$B$3,'ENTRY DATA'!EL13<='TABEL KONVERSI'!$C$3),1,IF(AND(EL13>='TABEL KONVERSI'!$B$4,'ENTRY DATA'!EL13<='TABEL KONVERSI'!$C$4),2,IF(AND(EL13>='TABEL KONVERSI'!$B$5,'ENTRY DATA'!EL13<='TABEL KONVERSI'!$C$5),3,IF(AND(EL13>='TABEL KONVERSI'!$B$6,'ENTRY DATA'!EL13<='TABEL KONVERSI'!$C$6),4,"")))),"-") -> - | EO13: =IF(EM13<>"",IF(AND(EM13>='TABEL KONVERSI'!$B$3,'ENTRY DATA'!EM13<='TABEL KONVERSI'!$C$3),1,IF(AND(EM13>='TABEL KONVERSI'!$B$4,'ENTRY DATA'!EM13<='TABEL KONVERSI'!$C$4),2,IF(AND(EM13>='TABEL KONVERSI'!$B$5,'ENTRY DATA'!EM13<='TABEL KONVERSI'!$C$5),3,IF(AND(EM13>='TABEL KONVERSI'!$B$6,'ENTRY DATA'!EM13<='TABEL KONVERSI'!$C$6),4,"")))),"-") -> - | EP13: =IF(EL13<>"",EL13,"-") -> - | EQ13: =VLOOKUP(EN13,'TABEL KONVERSI'!$A$3:$D$7,4) -> - | ER13: =IF(EM13<>"",EM13,"-") -> - | ES13: =VLOOKUP(EO13,'TABEL KONVERSI'!$A$3:$D$7,4) -> - | EX13: =IF(ET13<>"",ROUND(ET13,0),"") | EY13: =IF(EU13<>"",ROUND(EU13,0),"") | EZ13: =IF(EX13<>"",IF(AND(EX13>='TABEL KONVERSI'!$B$3,'ENTRY DATA'!EX13<='TABEL KONVERSI'!$C$3),1,IF(AND(EX13>='TABEL KONVERSI'!$B$4,'ENTRY DATA'!EX13<='TABEL KONVERSI'!$C$4),2,IF(AND(EX13>='TABEL KONVERSI'!$B$5,'ENTRY DATA'!EX13<='TABEL KONVERSI'!$C$5),3,IF(AND(EX13>='TABEL KONVERSI'!$B$6,'ENTRY DATA'!EX13<='TABEL KONVERSI'!$C$6),4,"")))),"-") -> - | FA13: =IF(EY13<>"",IF(AND(EY13>='TABEL KONVERSI'!$B$3,'ENTRY DATA'!EY13<='TABEL KONVERSI'!$C$3),1,IF(AND(EY13>='TABEL KONVERSI'!$B$4,'ENTRY DATA'!EY13<='TABEL KONVERSI'!$C$4),2,IF(AND(EY13>='TABEL KONVERSI'!$B$5,'ENTRY DATA'!EY13<='TABEL KONVERSI'!$C$5),3,IF(AND(EY13>='TABEL KONVERSI'!$B$6,'ENTRY DATA'!EY13<='TABEL KONVERSI'!$C$6),4,"")))),"-") -> - | FB13: =IF(EX13<>"",EX13,"-") -> - | FC13: =VLOOKUP(EZ13,'TABEL KONVERSI'!$A$3:$D$7,4) -> - | FD13: =IF(EY13<>"",EY13,"-") -> - | FE13: =VLOOKUP(FA13,'TABEL KONVERSI'!$A$3:$D$7,4) -> - | FJ13: =IF(FF13<>"",ROUND(FF13,0),"") | FK13: =IF(FG13<>"",ROUND(FG13,0),"") | FL13: =IF(FJ13<>"",IF(AND(FJ13>='TABEL KONVERSI'!$B$3,'ENTRY DATA'!FJ13<='TABEL KONVERSI'!$C$3),1,IF(AND(FJ13>='TABEL KONVERSI'!$B$4,'ENTRY DATA'!FJ13<='TABEL KONVERSI'!$C$4),2,IF(AND(FJ13>='TABEL KONVERSI'!$B$5,'ENTRY DATA'!FJ13<='TABEL KONVERSI'!$C$5),3,IF(AND(FJ13>='TABEL KONVERSI'!$B$6,'ENTRY DATA'!FJ13<='TABEL KONVERSI'!$C$6),4,"")))),"-") -> - | FM13: =IF(FK13<>"",IF(AND(FK13>='TABEL KONVERSI'!$B$3,'ENTRY DATA'!FK13<='TABEL KONVERSI'!$C$3),1,IF(AND(FK13>='TABEL KONVERSI'!$B$4,'ENTRY DATA'!FK13<='TABEL KONVERSI'!$C$4),2,IF(AND(FK13>='TABEL KONVERSI'!$B$5,'ENTRY DATA'!FK13<='TABEL KONVERSI'!$C$5),3,IF(AND(FK13>='TABEL KONVERSI'!$B$6,'ENTRY DATA'!FK13<='TABEL KONVERSI'!$C$6),4,"")))),"-") -> - | FN13: =IF(FJ13<>"",FJ13,"-") -> - | FO13: =VLOOKUP(FL13,'TABEL KONVERSI'!$A$3:$D$7,4) -> - | FP13: =IF(FK13<>"",FK13,"-") -> - | FQ13: =VLOOKUP(FM13,'TABEL KONVERSI'!$A$3:$D$7,4) -> - | FV13: =IF(FR13<>"",ROUND(FR13,0),"") | FW13: =IF(FS13<>"",ROUND(FS13,0),"") | FX13: =IF(FV13<>"",IF(AND(FV13>='TABEL KONVERSI'!$B$3,'ENTRY DATA'!FV13<='TABEL KONVERSI'!$C$3),1,IF(AND(FV13>='TABEL KONVERSI'!$B$4,'ENTRY DATA'!FV13<='TABEL KONVERSI'!$C$4),2,IF(AND(FV13>='TABEL KONVERSI'!$B$5,'ENTRY DATA'!FV13<='TABEL KONVERSI'!$C$5),3,IF(AND(FV13>='TABEL KONVERSI'!$B$6,'ENTRY DATA'!FV13<='TABEL KONVERSI'!$C$6),4,"")))),"-") -> - | FY13: =IF(FW13<>"",IF(AND(FW13>='TABEL KONVERSI'!$B$3,'ENTRY DATA'!FW13<='TABEL KONVERSI'!$C$3),1,IF(AND(FW13>='TABEL KONVERSI'!$B$4,'ENTRY DATA'!FW13<='TABEL KONVERSI'!$C$4),2,IF(AND(FW13>='TABEL KONVERSI'!$B$5,'ENTRY DATA'!FW13<='TABEL KONVERSI'!$C$5),3,IF(AND(FW13>='TABEL KONVERSI'!$B$6,'ENTRY DATA'!FW13<='TABEL KONVERSI'!$C$6),4,"")))),"-") -> - | FZ13: =IF(FV13<>"",FV13,"-") -> - | GA13: =VLOOKUP(FX13,'TABEL KONVERSI'!$A$3:$D$7,4) -> - | GB13: =IF(FW13<>"",FW13,"-") -> - | GC13: =VLOOKUP(FY13,'TABEL KONVERSI'!$A$3:$D$7,4) -> - | GH13: =IF(GD13<>"",ROUND(GD13,0),"") | GI13: =IF(GE13<>"",ROUND(GE13,0),"") | GJ13: =IF(GH13<>"",IF(AND(GH13>='TABEL KONVERSI'!$B$3,'ENTRY DATA'!GH13<='TABEL KONVERSI'!$C$3),1,IF(AND(GH13>='TABEL KONVERSI'!$B$4,'ENTRY DATA'!GH13<='TABEL KONVERSI'!$C$4),2,IF(AND(GH13>='TABEL KONVERSI'!$B$5,'ENTRY DATA'!GH13<='TABEL KONVERSI'!$C$5),3,IF(AND(GH13>='TABEL KONVERSI'!$B$6,'ENTRY DATA'!GH13<='TABEL KONVERSI'!$C$6),4,"")))),"-") -> - | GK13: =IF(GI13<>"",IF(AND(GI13>='TABEL KONVERSI'!$B$3,'ENTRY DATA'!GI13<='TABEL KONVERSI'!$C$3),1,IF(AND(GI13>='TABEL KONVERSI'!$B$4,'ENTRY DATA'!GI13<='TABEL KONVERSI'!$C$4),2,IF(AND(GI13>='TABEL KONVERSI'!$B$5,'ENTRY DATA'!GI13<='TABEL KONVERSI'!$C$5),3,IF(AND(GI13>='TABEL KONVERSI'!$B$6,'ENTRY DATA'!GI13<='TABEL KONVERSI'!$C$6),4,"")))),"-") -> - | GL13: =IF(GH13<>"",GH13,"-") -> - | GM13: =VLOOKUP(GJ13,'TABEL KONVERSI'!$A$3:$D$7,4) -> - | GN13: =IF(GI13<>"",GI13,"-") -> - | GO13: =VLOOKUP(GK13,'TABEL KONVERSI'!$A$3:$D$7,4) -> - | GP13: =H13 -> 0 | GQ13: =T13 -> 0 | GR13: =AF13 -> 0 | GS13: =AR13 -> 0 | GT13: =BD13 -> 0 | GU13: =BP13 -> 0 | GV13: =CB13 -> 0 | GW13: =CN13 -> 0 | GX13: =CZ13 -> 0 | GY13: =DL13 -> 0 | GZ13: =DX13 -> 0 | HA13: =EJ13 -> 0 | HB13: =EV13 -> 0 | HC13: =FH13 -> 0 | HD13: =FT13 -> 0 | HE13: =GF13 -> 0 | HF13: =COUNTIF($GP13:$HE13,"=A") -> 0 | HG13: =COUNTIF($GP13:$HE13,"=B") -> 0 | HH13: =COUNTIF($GP13:$HE13,"=C") -> 0 | HI13: =COUNTIF($GP13:$HE13,"=D") -> 0 | HJ13: =IF(AND(HF13=0,HG13=0,HH13=0,HI13=0),"-",IF(MAX(HF13:HI13)=HF13,"A",IF(MAX(HF13:HI13)=HG13,"B",IF(MAX(HF13:HI13)=HH13,"C",IF(MAX(HF13:HI13)=HI13,"D","-"))))) -> - | HK13: =VLOOKUP(HJ13,'TABEL KONVERSI'!$B$11:$D$15,2,0) -> - | HL13: =I13 -> 0 | HM13: =U13 -> 0 | HN13: =AG13 -> 0 | HO13: =AS13 -> 0 | HP13: =BE13 -> 0 | HQ13: =BQ13 -> 0 | HR13: =CC13 -> 0 | HS13: =CO13 -> 0 | HT13: =DA13 -> 0 | HU13: =DM13 -> 0 | HV13: =DY13 -> 0 | HW13: =EK13 -> 0 | HX13: =EW13 -> 0 | HY13: =FI13 -> 0 | HZ13: =FU13 -> 0 | IA13: =GG13 -> 0 | IB13: =COUNTIF($HL13:$IA13,"=A") -> 0 | IC13: =COUNTIF($HL13:$IA13,"=B") -> 0 | ID13: =COUNTIF($HL13:$IA13,"=C") -> 0 | IE13: =COUNTIF($HL13:$IA13,"=D") -> 0 | IF13: =IF(AND(IB13=0,IC13=0,ID13=0,IE13=0),"-",IF(MAX(IB13:IE13)=IB13,"A",IF(MAX(IB13:IE13)=IC13,"B",IF(MAX(IB13:IE13)=ID13,"C",IF(MAX(IB13:IE13)=IE13,"D","-"))))) -> - | IG13: =VLOOKUP(IF13,'TABEL KONVERSI'!$B$11:$D$15,3,0) -> - | IH13: Pramuka | II13: B | IJ13: =IF(II13<>"",VLOOKUP(II13,'TABEL KONVERSI'!$A$19:$B$23,2,0),"") -> Aktif dalam mengikuti kegiatan | IK13: - | IL13: - | IM13: =IF(IL13<>"",VLOOKUP(IL13,'TABEL KONVERSI'!$A$19:$B$23,2,0),"") -> - | IN13: - | IO13: - | IP13: =IF(IO13<>"",VLOOKUP(IO13,'TABEL KONVERSI'!$A$19:$B$23,2,0),"") -> - | IQ13: - | IR13: - | IS13: =IF(IR13<>"",VLOOKUP(IR13,'TABEL KONVERSI'!$A$19:$B$23,2,0),"") -> - | IT13: - | IU13: - | IV13: =IF(IU13<>"",VLOOKUP(IU13,'TABEL KONVERSI'!$A$19:$B$23,2,0),"") -> - | IW13: - | IX13: - | IY13: - | IZ13: - | JA13: =SUM(N13,P13,Z13,AB13,AL13,AN13,AX13,AZ13,BJ13,BL13,BV13,BX13,CH13,CJ13,CT13,CV13,DF13,DH13,DR13,DT13,ED13,EF13,EP13,ER13,FB13,FD13,FN13,FP13,FZ13,GB13,GL13,GN13) -> 0 | JB13: =RANK(JA13,$JA$13:$JA$62,0) -> 1
A14: 2 | J14: =IF(F14<>"",ROUND(F14,0),"") | K14: =IF(G14<>"",ROUND(G14,0),"") | L14: =IF(J14<>"",IF(AND(J14>='TABEL KONVERSI'!$B$3,'ENTRY DATA'!J14<='TABEL KONVERSI'!$C$3),1,IF(AND(J14>='TABEL KONVERSI'!$B$4,'ENTRY DATA'!J14<='TABEL KONVERSI'!$C$4),2,IF(AND(J14>='TABEL KONVERSI'!$B$5,'ENTRY DATA'!J14<='TABEL KONVERSI'!$C$5),3,IF(AND(J14>='TABEL KONVERSI'!$B$6,'ENTRY DATA'!J14<='TABEL KONVERSI'!$C$6),4,"")))),"-") -> - | M14: =IF(K14<>"",IF(AND(K14>='TABEL KONVERSI'!$B$3,'ENTRY DATA'!K14<='TABEL KONVERSI'!$C$3),1,IF(AND(K14>='TABEL KONVERSI'!$B$4,'ENTRY DATA'!K14<='TABEL KONVERSI'!$C$4),2,IF(AND(K14>='TABEL KONVERSI'!$B$5,'ENTRY DATA'!K14<='TABEL KONVERSI'!$C$5),3,IF(AND(K14>='TABEL KONVERSI'!$B$6,'ENTRY DATA'!K14<='TABEL KONVERSI'!$C$6),4,"")))),"-") -> - | N14: =IF(J14<>"",J14,"-") -> - | O14: =VLOOKUP(L14,'TABEL KONVERSI'!$A$3:$D$7,4) -> - | P14: =IF(K14<>"",K14,"-") -> - | Q14: =VLOOKUP(M14,'TABEL KONVERSI'!$A$3:$D$7,4) -> - | V14: =IF(R14<>"",ROUND(R14,0),"") | W14: =IF(S14<>"",ROUND(S14,0),"") | X14: =IF(V14<>"",IF(AND(V14>='TABEL KONVERSI'!$B$3,'ENTRY DATA'!V14<='TABEL KONVERSI'!$C$3),1,IF(AND(V14>='TABEL KONVERSI'!$B$4,'ENTRY DATA'!V14<='TABEL KONVERSI'!$C$4),2,IF(AND(V14>='TABEL KONVERSI'!$B$5,'ENTRY DATA'!V14<='TABEL KONVERSI'!$C$5),3,IF(AND(V14>='TABEL KONVERSI'!$B$6,'ENTRY DATA'!V14<='TABEL KONVERSI'!$C$6),4,"")))),"-") -> - | Y14: =IF(W14<>"",IF(AND(W14>='TABEL KONVERSI'!$B$3,'ENTRY DATA'!W14<='TABEL KONVERSI'!$C$3),1,IF(AND(W14>='TABEL KONVERSI'!$B$4,'ENTRY DATA'!W14<='TABEL KONVERSI'!$C$4),2,IF(AND(W14>='TABEL KONVERSI'!$B$5,'ENTRY DATA'!W14<='TABEL KONVERSI'!$C$5),3,IF(AND(W14>='TABEL KONVERSI'!$B$6,'ENTRY DATA'!W14<='TABEL KONVERSI'!$C$6),4,"")))),"-") -> - | Z14: =IF(V14<>"",V14,"-") -> - | AA14: =VLOOKUP(X14,'TABEL KONVERSI'!$A$3:$D$7,4) -> - | AB14: =IF(W14<>"",W14,"-") -> - | AC14: =VLOOKUP(Y14,'TABEL KONVERSI'!$A$3:$D$7,4) -> - | AH14: =IF(AD14<>"",ROUND(AD14,0),"") | AI14: =IF(AE14<>"",ROUND(AE14,0),"") | AJ14: =IF(AH14<>"",IF(AND(AH14>='TABEL KONVERSI'!$B$3,'ENTRY DATA'!AH14<='TABEL KONVERSI'!$C$3),1,IF(AND(AH14>='TABEL KONVERSI'!$B$4,'ENTRY DATA'!AH14<='TABEL KONVERSI'!$C$4),2,IF(AND(AH14>='TABEL KONVERSI'!$B$5,'ENTRY DATA'!AH14<='TABEL KONVERSI'!$C$5),3,IF(AND(AH14>='TABEL KONVERSI'!$B$6,'ENTRY DATA'!AH14<='TABEL KONVERSI'!$C$6),4,"")))),"-") -> - | AK14: =IF(AI14<>"",IF(AND(AI14>='TABEL KONVERSI'!$B$3,'ENTRY DATA'!AI14<='TABEL KONVERSI'!$C$3),1,IF(AND(AI14>='TABEL KONVERSI'!$B$4,'ENTRY DATA'!AI14<='TABEL KONVERSI'!$C$4),2,IF(AND(AI14>='TABEL KONVERSI'!$B$5,'ENTRY DATA'!AI14<='TABEL KONVERSI'!$C$5),3,IF(AND(AI14>='TABEL KONVERSI'!$B$6,'ENTRY DATA'!AI14<='TABEL KONVERSI'!$C$6),4,"")))),"-") -> - | AL14: =IF(AH14<>"",AH14,"-") -> - | AM14: =VLOOKUP(AJ14,'TABEL KONVERSI'!$A$3:$D$7,4) -> - | AN14: =IF(AI14<>"",AI14,"-") -> - | AO14: =VLOOKUP(AK14,'TABEL KONVERSI'!$A$3:$D$7,4) -> - | AT14: =IF(AP14<>"",ROUND(AP14,0),"") | AU14: =IF(AQ14<>"",ROUND(AQ14,0),"") | AV14: =IF(AT14<>"",IF(AND(AT14>='TABEL KONVERSI'!$B$3,'ENTRY DATA'!AT14<='TABEL KONVERSI'!$C$3),1,IF(AND(AT14>='TABEL KONVERSI'!$B$4,'ENTRY DATA'!AT14<='TABEL KONVERSI'!$C$4),2,IF(AND(AT14>='TABEL KONVERSI'!$B$5,'ENTRY DATA'!AT14<='TABEL KONVERSI'!$C$5),3,IF(AND(AT14>='TABEL KONVERSI'!$B$6,'ENTRY DATA'!AT14<='TABEL KONVERSI'!$C$6),4,"")))),"-") -> - | AW14: =IF(AU14<>"",IF(AND(AU14>='TABEL KONVERSI'!$B$3,'ENTRY DATA'!AU14<='TABEL KONVERSI'!$C$3),1,IF(AND(AU14>='TABEL KONVERSI'!$B$4,'ENTRY DATA'!AU14<='TABEL KONVERSI'!$C$4),2,IF(AND(AU14>='TABEL KONVERSI'!$B$5,'ENTRY DATA'!AU14<='TABEL KONVERSI'!$C$5),3,IF(AND(AU14>='TABEL KONVERSI'!$B$6,'ENTRY DATA'!AU14<='TABEL KONVERSI'!$C$6),4,"")))),"-") -> - | AX14: =IF(AT14<>"",AT14,"-") -> - | AY14: =VLOOKUP(AV14,'TABEL KONVERSI'!$A$3:$D$7,4) -> - | AZ14: =IF(AU14<>"",AU14,"-") -> - | BA14: =VLOOKUP(AW14,'TABEL KONVERSI'!$A$3:$D$7,4) -> - | BF14: =IF(BB14<>"",ROUND(BB14,0),"") | BG14: =IF(BC14<>"",ROUND(BC14,0),"") | BH14: =IF(BF14<>"",IF(AND(BF14>='TABEL KONVERSI'!$B$3,'ENTRY DATA'!BF14<='TABEL KONVERSI'!$C$3),1,IF(AND(BF14>='TABEL KONVERSI'!$B$4,'ENTRY DATA'!BF14<='TABEL KONVERSI'!$C$4),2,IF(AND(BF14>='TABEL KONVERSI'!$B$5,'ENTRY DATA'!BF14<='TABEL KONVERSI'!$C$5),3,IF(AND(BF14>='TABEL KONVERSI'!$B$6,'ENTRY DATA'!BF14<='TABEL KONVERSI'!$C$6),4,"")))),"-") -> - | BI14: =IF(BG14<>"",IF(AND(BG14>='TABEL KONVERSI'!$B$3,'ENTRY DATA'!BG14<='TABEL KONVERSI'!$C$3),1,IF(AND(BG14>='TABEL KONVERSI'!$B$4,'ENTRY DATA'!BG14<='TABEL KONVERSI'!$C$4),2,IF(AND(BG14>='TABEL KONVERSI'!$B$5,'ENTRY DATA'!BG14<='TABEL KONVERSI'!$C$5),3,IF(AND(BG14>='TABEL KONVERSI'!$B$6,'ENTRY DATA'!BG14<='TABEL KONVERSI'!$C$6),4,"")))),"-") -> - | BJ14: =IF(BF14<>"",BF14,"-") -> - | BK14: =VLOOKUP(BH14,'TABEL KONVERSI'!$A$3:$D$7,4) -> - | BL14: =IF(BG14<>"",BG14,"-") -> - | BM14: =VLOOKUP(BI14,'TABEL KONVERSI'!$A$3:$D$7,4) -> - | BR14: =IF(BN14<>"",ROUND(BN14,0),"") | BS14: =IF(BO14<>"",ROUND(BO14,0),"") | BT14: =IF(BR14<>"",IF(AND(BR14>='TABEL KONVERSI'!$B$3,'ENTRY DATA'!BR14<='TABEL KONVERSI'!$C$3),1,IF(AND(BR14>='TABEL KONVERSI'!$B$4,'ENTRY DATA'!BR14<='TABEL KONVERSI'!$C$4),2,IF(AND(BR14>='TABEL KONVERSI'!$B$5,'ENTRY DATA'!BR14<='TABEL KONVERSI'!$C$5),3,IF(AND(BR14>='TABEL KONVERSI'!$B$6,'ENTRY DATA'!BR14<='TABEL KONVERSI'!$C$6),4,"")))),"-") -> - | BU14: =IF(BS14<>"",IF(AND(BS14>='TABEL KONVERSI'!$B$3,'ENTRY DATA'!BS14<='TABEL KONVERSI'!$C$3),1,IF(AND(BS14>='TABEL KONVERSI'!$B$4,'ENTRY DATA'!BS14<='TABEL KONVERSI'!$C$4),2,IF(AND(BS14>='TABEL KONVERSI'!$B$5,'ENTRY DATA'!BS14<='TABEL KONVERSI'!$C$5),3,IF(AND(BS14>='TABEL KONVERSI'!$B$6,'ENTRY DATA'!BS14<='TABEL KONVERSI'!$C$6),4,"")))),"-") -> - | BV14: =IF(BR14<>"",BR14,"-") -> - | BW14: =VLOOKUP(BT14,'TABEL KONVERSI'!$A$3:$D$7,4) -> - | BX14: =IF(BS14<>"",BS14,"-") -> - | BY14: =VLOOKUP(BU14,'TABEL KONVERSI'!$A$3:$D$7,4) -> - | CD14: =IF(BZ14<>"",ROUND(BZ14,0),"") | CE14: =IF(CA14<>"",ROUND(CA14,0),"") | CF14: =IF(CD14<>"",IF(AND(CD14>='TABEL KONVERSI'!$B$3,'ENTRY DATA'!CD14<='TABEL KONVERSI'!$C$3),1,IF(AND(CD14>='TABEL KONVERSI'!$B$4,'ENTRY DATA'!CD14<='TABEL KONVERSI'!$C$4),2,IF(AND(CD14>='TABEL KONVERSI'!$B$5,'ENTRY DATA'!CD14<='TABEL KONVERSI'!$C$5),3,IF(AND(CD14>='TABEL KONVERSI'!$B$6,'ENTRY DATA'!CD14<='TABEL KONVERSI'!$C$6),4,"")))),"-") -> - | CG14: =IF(CE14<>"",IF(AND(CE14>='TABEL KONVERSI'!$B$3,'ENTRY DATA'!CE14<='TABEL KONVERSI'!$C$3),1,IF(AND(CE14>='TABEL KONVERSI'!$B$4,'ENTRY DATA'!CE14<='TABEL KONVERSI'!$C$4),2,IF(AND(CE14>='TABEL KONVERSI'!$B$5,'ENTRY DATA'!CE14<='TABEL KONVERSI'!$C$5),3,IF(AND(CE14>='TABEL KONVERSI'!$B$6,'ENTRY DATA'!CE14<='TABEL KONVERSI'!$C$6),4,"")))),"-") -> - | CH14: =IF(CD14<>"",CD14,"-") -> - | CI14: =VLOOKUP(CF14,'TABEL KONVERSI'!$A$3:$D$7,4) -> - | CJ14: =IF(CE14<>"",CE14,"-") -> - | CK14: =VLOOKUP(CG14,'TABEL KONVERSI'!$A$3:$D$7,4) -> - | CP14: =IF(CL14<>"",ROUND(CL14,0),"") | CQ14: =IF(CM14<>"",ROUND(CM14,0),"") | CR14: =IF(CP14<>"",IF(AND(CP14>='TABEL KONVERSI'!$B$3,'ENTRY DATA'!CP14<='TABEL KONVERSI'!$C$3),1,IF(AND(CP14>='TABEL KONVERSI'!$B$4,'ENTRY DATA'!CP14<='TABEL KONVERSI'!$C$4),2,IF(AND(CP14>='TABEL KONVERSI'!$B$5,'ENTRY DATA'!CP14<='TABEL KONVERSI'!$C$5),3,IF(AND(CP14>='TABEL KONVERSI'!$B$6,'ENTRY DATA'!CP14<='TABEL KONVERSI'!$C$6),4,"")))),"-") -> - | CS14: =IF(CQ14<>"",IF(AND(CQ14>='TABEL KONVERSI'!$B$3,'ENTRY DATA'!CQ14<='TABEL KONVERSI'!$C$3),1,IF(AND(CQ14>='TABEL KONVERSI'!$B$4,'ENTRY DATA'!CQ14<='TABEL KONVERSI'!$C$4),2,IF(AND(CQ14>='TABEL KONVERSI'!$B$5,'ENTRY DATA'!CQ14<='TABEL KONVERSI'!$C$5),3,IF(AND(CQ14>='TABEL KONVERSI'!$B$6,'ENTRY DATA'!CQ14<='TABEL KONVERSI'!$C$6),4,"")))),"-") -> - | CT14: =IF(CP14<>"",CP14,"-") -> - | CU14: =VLOOKUP(CR14,'TABEL KONVERSI'!$A$3:$D$7,4) -> - | CV14: =IF(CQ14<>"",CQ14,"-") -> - | CW14: =VLOOKUP(CS14,'TABEL KONVERSI'!$A$3:$D$7,4) -> - | DB14: =IF(CX14<>"",ROUND(CX14,0),"") | DC14: =IF(CY14<>"",ROUND(CY14,0),"") | DD14: =IF(DB14<>"",IF(AND(DB14>='TABEL KONVERSI'!$B$3,'ENTRY DATA'!DB14<='TABEL KONVERSI'!$C$3),1,IF(AND(DB14>='TABEL KONVERSI'!$B$4,'ENTRY DATA'!DB14<='TABEL KONVERSI'!$C$4),2,IF(AND(DB14>='TABEL KONVERSI'!$B$5,'ENTRY DATA'!DB14<='TABEL KONVERSI'!$C$5),3,IF(AND(DB14>='TABEL KONVERSI'!$B$6,'ENTRY DATA'!DB14<='TABEL KONVERSI'!$C$6),4,"")))),"-") -> - | DE14: =IF(DC14<>"",IF(AND(DC14>='TABEL KONVERSI'!$B$3,'ENTRY DATA'!DC14<='TABEL KONVERSI'!$C$3),1,IF(AND(DC14>='TABEL KONVERSI'!$B$4,'ENTRY DATA'!DC14<='TABEL KONVERSI'!$C$4),2,IF(AND(DC14>='TABEL KONVERSI'!$B$5,'ENTRY DATA'!DC14<='TABEL KONVERSI'!$C$5),3,IF(AND(DC14>='TABEL KONVERSI'!$B$6,'ENTRY DATA'!DC14<='TABEL KONVERSI'!$C$6),4,"")))),"-") -> - | DF14: =IF(DB14<>"",DB14,"-") -> - | DG14: =VLOOKUP(DD14,'TABEL KONVERSI'!$A$3:$D$7,4) -> - | DH14: =IF(DC14<>"",DC14,"-") -> - | DI14: =VLOOKUP(DE14,'TABEL KONVERSI'!$A$3:$D$7,4) -> - | DN14: =IF(DJ14<>"",ROUND(DJ14,0),"") | DO14: =IF(DK14<>"",ROUND(DK14,0),"") | DP14: =IF(DN14<>"",IF(AND(DN14>='TABEL KONVERSI'!$B$3,'ENTRY DATA'!DN14<='TABEL KONVERSI'!$C$3),1,IF(AND(DN14>='TABEL KONVERSI'!$B$4,'ENTRY DATA'!DN14<='TABEL KONVERSI'!$C$4),2,IF(AND(DN14>='TABEL KONVERSI'!$B$5,'ENTRY DATA'!DN14<='TABEL KONVERSI'!$C$5),3,IF(AND(DN14>='TABEL KONVERSI'!$B$6,'ENTRY DATA'!DN14<='TABEL KONVERSI'!$C$6),4,"")))),"-") -> - | DQ14: =IF(DO14<>"",IF(AND(DO14>='TABEL KONVERSI'!$B$3,'ENTRY DATA'!DO14<='TABEL KONVERSI'!$C$3),1,IF(AND(DO14>='TABEL KONVERSI'!$B$4,'ENTRY DATA'!DO14<='TABEL KONVERSI'!$C$4),2,IF(AND(DO14>='TABEL KONVERSI'!$B$5,'ENTRY DATA'!DO14<='TABEL KONVERSI'!$C$5),3,IF(AND(DO14>='TABEL KONVERSI'!$B$6,'ENTRY DATA'!DO14<='TABEL KONVERSI'!$C$6),4,"")))),"-") -> - | DR14: =IF(DN14<>"",DN14,"-") -> - | DS14: =VLOOKUP(DP14,'TABEL KONVERSI'!$A$3:$D$7,4) -> - | DT14: =IF(DO14<>"",DO14,"-") -> - | DU14: =VLOOKUP(DQ14,'TABEL KONVERSI'!$A$3:$D$7,4) -> - | DZ14: =IF(DV14<>"",ROUND(DV14,0),"") | EA14: =IF(DW14<>"",ROUND(DW14,0),"") | EB14: =IF(DZ14<>"",IF(AND(DZ14>='TABEL KONVERSI'!$B$3,'ENTRY DATA'!DZ14<='TABEL KONVERSI'!$C$3),1,IF(AND(DZ14>='TABEL KONVERSI'!$B$4,'ENTRY DATA'!DZ14<='TABEL KONVERSI'!$C$4),2,IF(AND(DZ14>='TABEL KONVERSI'!$B$5,'ENTRY DATA'!DZ14<='TABEL KONVERSI'!$C$5),3,IF(AND(DZ14>='TABEL KONVERSI'!$B$6,'ENTRY DATA'!DZ14<='TABEL KONVERSI'!$C$6),4,"")))),"-") -> - | EC14: =IF(EA14<>"",IF(AND(EA14>='TABEL KONVERSI'!$B$3,'ENTRY DATA'!EA14<='TABEL KONVERSI'!$C$3),1,IF(AND(EA14>='TABEL KONVERSI'!$B$4,'ENTRY DATA'!EA14<='TABEL KONVERSI'!$C$4),2,IF(AND(EA14>='TABEL KONVERSI'!$B$5,'ENTRY DATA'!EA14<='TABEL KONVERSI'!$C$5),3,IF(AND(EA14>='TABEL KONVERSI'!$B$6,'ENTRY DATA'!EA14<='TABEL KONVERSI'!$C$6),4,"")))),"-") -> - | ED14: =IF(DZ14<>"",DZ14,"-") -> - | EE14: =VLOOKUP(EB14,'TABEL KONVERSI'!$A$3:$D$7,4) -> - | EF14: =IF(EA14<>"",EA14,"-") -> - | EG14: =VLOOKUP(EC14,'TABEL KONVERSI'!$A$3:$D$7,4) -> - | EL14: =IF(EH14<>"",ROUND(EH14,0),"") | EM14: =IF(EI14<>"",ROUND(EI14,0),"") | EN14: =IF(EL14<>"",IF(AND(EL14>='TABEL KONVERSI'!$B$3,'ENTRY DATA'!EL14<='TABEL KONVERSI'!$C$3),1,IF(AND(EL14>='TABEL KONVERSI'!$B$4,'ENTRY DATA'!EL14<='TABEL KONVERSI'!$C$4),2,IF(AND(EL14>='TABEL KONVERSI'!$B$5,'ENTRY DATA'!EL14<='TABEL KONVERSI'!$C$5),3,IF(AND(EL14>='TABEL KONVERSI'!$B$6,'ENTRY DATA'!EL14<='TABEL KONVERSI'!$C$6),4,"")))),"-") -> - | EO14: =IF(EM14<>"",IF(AND(EM14>='TABEL KONVERSI'!$B$3,'ENTRY DATA'!EM14<='TABEL KONVERSI'!$C$3),1,IF(AND(EM14>='TABEL KONVERSI'!$B$4,'ENTRY DATA'!EM14<='TABEL KONVERSI'!$C$4),2,IF(AND(EM14>='TABEL KONVERSI'!$B$5,'ENTRY DATA'!EM14<='TABEL KONVERSI'!$C$5),3,IF(AND(EM14>='TABEL KONVERSI'!$B$6,'ENTRY DATA'!EM14<='TABEL KONVERSI'!$C$6),4,"")))),"-") -> - | EP14: =IF(EL14<>"",EL14,"-") -> - | EQ14: =VLOOKUP(EN14,'TABEL KONVERSI'!$A$3:$D$7,4) -> - | ER14: =IF(EM14<>"",EM14,"-") -> - | ES14: =VLOOKUP(EO14,'TABEL KONVERSI'!$A$3:$D$7,4) -> - | EX14: =IF(ET14<>"",ROUND(ET14,0),"") | EY14: =IF(EU14<>"",ROUND(EU14,0),"") | EZ14: =IF(EX14<>"",IF(AND(EX14>='TABEL KONVERSI'!$B$3,'ENTRY DATA'!EX14<='TABEL KONVERSI'!$C$3),1,IF(AND(EX14>='TABEL KONVERSI'!$B$4,'ENTRY DATA'!EX14<='TABEL KONVERSI'!$C$4),2,IF(AND(EX14>='TABEL KONVERSI'!$B$5,'ENTRY DATA'!EX14<='TABEL KONVERSI'!$C$5),3,IF(AND(EX14>='TABEL KONVERSI'!$B$6,'ENTRY DATA'!EX14<='TABEL KONVERSI'!$C$6),4,"")))),"-") -> - | FA14: =IF(EY14<>"",IF(AND(EY14>='TABEL KONVERSI'!$B$3,'ENTRY DATA'!EY14<='TABEL KONVERSI'!$C$3),1,IF(AND(EY14>='TABEL KONVERSI'!$B$4,'ENTRY DATA'!EY14<='TABEL KONVERSI'!$C$4),2,IF(AND(EY14>='TABEL KONVERSI'!$B$5,'ENTRY DATA'!EY14<='TABEL KONVERSI'!$C$5),3,IF(AND(EY14>='TABEL KONVERSI'!$B$6,'ENTRY DATA'!EY14<='TABEL KONVERSI'!$C$6),4,"")))),"-") -> - | FB14: =IF(EX14<>"",EX14,"-") -> - | FC14: =VLOOKUP(EZ14,'TABEL KONVERSI'!$A$3:$D$7,4) -> - | FD14: =IF(EY14<>"",EY14,"-") -> - | FE14: =VLOOKUP(FA14,'TABEL KONVERSI'!$A$3:$D$7,4) -> - | FJ14: =IF(FF14<>"",ROUND(FF14,0),"") | FK14: =IF(FG14<>"",ROUND(FG14,0),"") | FL14: =IF(FJ14<>"",IF(AND(FJ14>='TABEL KONVERSI'!$B$3,'ENTRY DATA'!FJ14<='TABEL KONVERSI'!$C$3),1,IF(AND(FJ14>='TABEL KONVERSI'!$B$4,'ENTRY DATA'!FJ14<='TABEL KONVERSI'!$C$4),2,IF(AND(FJ14>='TABEL KONVERSI'!$B$5,'ENTRY DATA'!FJ14<='TABEL KONVERSI'!$C$5),3,IF(AND(FJ14>='TABEL KONVERSI'!$B$6,'ENTRY DATA'!FJ14<='TABEL KONVERSI'!$C$6),4,"")))),"-") -> - | FM14: =IF(FK14<>"",IF(AND(FK14>='TABEL KONVERSI'!$B$3,'ENTRY DATA'!FK14<='TABEL KONVERSI'!$C$3),1,IF(AND(FK14>='TABEL KONVERSI'!$B$4,'ENTRY DATA'!FK14<='TABEL KONVERSI'!$C$4),2,IF(AND(FK14>='TABEL KONVERSI'!$B$5,'ENTRY DATA'!FK14<='TABEL KONVERSI'!$C$5),3,IF(AND(FK14>='TABEL KONVERSI'!$B$6,'ENTRY DATA'!FK14<='TABEL KONVERSI'!$C$6),4,"")))),"-") -> - | FN14: =IF(FJ14<>"",FJ14,"-") -> - | FO14: =VLOOKUP(FL14,'TABEL KONVERSI'!$A$3:$D$7,4) -> - | FP14: =IF(FK14<>"",FK14,"-") -> - | FQ14: =VLOOKUP(FM14,'TABEL KONVERSI'!$A$3:$D$7,4) -> - | FV14: =IF(FR14<>"",ROUND(FR14,0),"") | FW14: =IF(FS14<>"",ROUND(FS14,0),"") | FX14: =IF(FV14<>"",IF(AND(FV14>='TABEL KONVERSI'!$B$3,'ENTRY DATA'!FV14<='TABEL KONVERSI'!$C$3),1,IF(AND(FV14>='TABEL KONVERSI'!$B$4,'ENTRY DATA'!FV14<='TABEL KONVERSI'!$C$4),2,IF(AND(FV14>='TABEL KONVERSI'!$B$5,'ENTRY DATA'!FV14<='TABEL KONVERSI'!$C$5),3,IF(AND(FV14>='TABEL KONVERSI'!$B$6,'ENTRY DATA'!FV14<='TABEL KONVERSI'!$C$6),4,"")))),"-") -> - | FY14: =IF(FW14<>"",IF(AND(FW14>='TABEL KONVERSI'!$B$3,'ENTRY DATA'!FW14<='TABEL KONVERSI'!$C$3),1,IF(AND(FW14>='TABEL KONVERSI'!$B$4,'ENTRY DATA'!FW14<='TABEL KONVERSI'!$C$4),2,IF(AND(FW14>='TABEL KONVERSI'!$B$5,'ENTRY DATA'!FW14<='TABEL KONVERSI'!$C$5),3,IF(AND(FW14>='TABEL KONVERSI'!$B$6,'ENTRY DATA'!FW14<='TABEL KONVERSI'!$C$6),4,"")))),"-") -> - | FZ14: =IF(FV14<>"",FV14,"-") -> - | GA14: =VLOOKUP(FX14,'TABEL KONVERSI'!$A$3:$D$7,4) -> - | GB14: =IF(FW14<>"",FW14,"-") -> - | GC14: =VLOOKUP(FY14,'TABEL KONVERSI'!$A$3:$D$7,4) -> - | GH14: =IF(GD14<>"",ROUND(GD14,0),"") | GI14: =IF(GE14<>"",ROUND(GE14,0),"") | GJ14: =IF(GH14<>"",IF(AND(GH14>='TABEL KONVERSI'!$B$3,'ENTRY DATA'!GH14<='TABEL KONVERSI'!$C$3),1,IF(AND(GH14>='TABEL KONVERSI'!$B$4,'ENTRY DATA'!GH14<='TABEL KONVERSI'!$C$4),2,IF(AND(GH14>='TABEL KONVERSI'!$B$5,'ENTRY DATA'!GH14<='TABEL KONVERSI'!$C$5),3,IF(AND(GH14>='TABEL KONVERSI'!$B$6,'ENTRY DATA'!GH14<='TABEL KONVERSI'!$C$6),4,"")))),"-") -> - | GK14: =IF(GI14<>"",IF(AND(GI14>='TABEL KONVERSI'!$B$3,'ENTRY DATA'!GI14<='TABEL KONVERSI'!$C$3),1,IF(AND(GI14>='TABEL KONVERSI'!$B$4,'ENTRY DATA'!GI14<='TABEL KONVERSI'!$C$4),2,IF(AND(GI14>='TABEL KONVERSI'!$B$5,'ENTRY DATA'!GI14<='TABEL KONVERSI'!$C$5),3,IF(AND(GI14>='TABEL KONVERSI'!$B$6,'ENTRY DATA'!GI14<='TABEL KONVERSI'!$C$6),4,"")))),"-") -> - | GL14: =IF(GH14<>"",GH14,"-") -> - | GM14: =VLOOKUP(GJ14,'TABEL KONVERSI'!$A$3:$D$7,4) -> - | GN14: =IF(GI14<>"",GI14,"-") -> - | GO14: =VLOOKUP(GK14,'TABEL KONVERSI'!$A$3:$D$7,4) -> - | GP14: =H14 -> 0 | GQ14: =T14 -> 0 | GR14: =AF14 -> 0 | GS14: =AR14 -> 0 | GT14: =BD14 -> 0 | GU14: =BP14 -> 0 | GV14: =CB14 -> 0 | GW14: =CN14 -> 0 | GX14: =CZ14 -> 0 | GY14: =DL14 -> 0 | GZ14: =DX14 -> 0 | HA14: =EJ14 -> 0 | HB14: =EV14 -> 0 | HC14: =FH14 -> 0 | HD14: =FT14 -> 0 | HE14: =GF14 -> 0 | HF14: =COUNTIF($GP14:$HE14,"=A") -> 0 | HG14: =COUNTIF($GP14:$HE14,"=B") -> 0 | HH14: =COUNTIF($GP14:$HE14,"=C") -> 0 | HI14: =COUNTIF($GP14:$HE14,"=D") -> 0 | HJ14: =IF(AND(HF14=0,HG14=0,HH14=0,HI14=0),"-",IF(MAX(HF14:HI14)=HF14,"A",IF(MAX(HF14:HI14)=HG14,"B",IF(MAX(HF14:HI14)=HH14,"C",IF(MAX(HF14:HI14)=HI14,"D","-"))))) -> - | HK14: =VLOOKUP(HJ14,'TABEL KONVERSI'!$B$11:$D$15,2,0) -> - | HL14: =I14 -> 0 | HM14: =U14 -> 0 | HN14: =AG14 -> 0 | HO14: =AS14 -> 0 | HP14: =BE14 -> 0 | HQ14: =BQ14 -> 0 | HR14: =CC14 -> 0 | HS14: =CO14 -> 0 | HT14: =DA14 -> 0 | HU14: =DM14 -> 0 | HV14: =DY14 -> 0 | HW14: =EK14 -> 0 | HX14: =EW14 -> 0 | HY14: =FI14 -> 0 | HZ14: =FU14 -> 0 | IA14: =GG14 -> 0 | IB14: =COUNTIF($HL14:$IA14,"=A") -> 0 | IC14: =COUNTIF($HL14:$IA14,"=B") -> 0 | ID14: =COUNTIF($HL14:$IA14,"=C") -> 0 | IE14: =COUNTIF($HL14:$IA14,"=D") -> 0 | IF14: =IF(AND(IB14=0,IC14=0,ID14=0,IE14=0),"-",IF(MAX(IB14:IE14)=IB14,"A",IF(MAX(IB14:IE14)=IC14,"B",IF(MAX(IB14:IE14)=ID14,"C",IF(MAX(IB14:IE14)=IE14,"D","-"))))) -> - | IG14: =VLOOKUP(IF14,'TABEL KONVERSI'!$B$11:$D$15,3,0) -> - | IH14: Pramuka | II14: B | IJ14: =IF(II14<>"",VLOOKUP(II14,'TABEL KONVERSI'!$A$19:$B$23,2,0),"") -> Aktif dalam mengikuti kegiatan | IK14: - | IL14: - | IM14: =IF(IL14<>"",VLOOKUP(IL14,'TABEL KONVERSI'!$A$19:$B$23,2,0),"") -> - | IN14: - | IO14: - | IP14: =IF(IO14<>"",VLOOKUP(IO14,'TABEL KONVERSI'!$A$19:$B$23,2,0),"") -> - | IQ14: - | IR14: - | IS14: =IF(IR14<>"",VLOOKUP(IR14,'TABEL KONVERSI'!$A$19:$B$23,2,0),"") -> - | IT14: - | IU14: - | IV14: =IF(IU14<>"",VLOOKUP(IU14,'TABEL KONVERSI'!$A$19:$B$23,2,0),"") -> - | IW14: - | IX14: - | IY14: - | IZ14: - | JA14: =SUM(N14,P14,Z14,AB14,AL14,AN14,AX14,AZ14,BJ14,BL14,BV14,BX14,CH14,CJ14,CT14,CV14,DF14,DH14,DR14,DT14,ED14,EF14,EP14,ER14,FB14,FD14,FN14,FP14,FZ14,GB14,GL14,GN14) -> 0 | JB14: =RANK(JA14,$JA$13:$JA$62,0) -> 1
